{"tag": "function", "depth": 1, "time": 1742197501.6669986, "data": {"name": "connect_device", "call_args": {"uri": "Android://127.0.0.1:5037/23E0224711011260"}, "start_time": 1742197496.5942798, "traceback": "Traceback (most recent call last):\n  File \"D:\\ww 2\\venv\\Lib\\site-packages\\airtest\\core\\android\\adb.py\", line 341, in wait_for_device\n    self.cmd(\"wait-for-device\", timeout=timeout)\n  File \"D:\\ww 2\\venv\\Lib\\site-packages\\airtest\\core\\android\\adb.py\", line 221, in cmd\n    stdout, stderr = proc_communicate_timeout(proc, timeout)\n                     ^^^^^^^^^^^^^^^^^^^^^^^^^^^^^^^^^^^^^^^\n  File \"D:\\ww 2\\venv\\Lib\\site-packages\\airtest\\utils\\compat.py\", line 79, in proc_communicate_timeout\n    raise_from(exp, None)\n  File \"<string>\", line 3, in raise_from\nRuntimeError: Command ['C:\\\\Users\\\\ASUS\\\\AppData\\\\Local\\\\Android\\\\android-sdk\\\\platform-tools\\\\adb.exe', '-P', '5037', '-s', '23E0224711011260', 'wait-for-device'] timed out after 5 seconds: stdout['b'''], stderr['b''']\n\nThe above exception was the direct cause of the following exception:\n\nTraceback (most recent call last):\n  File \"D:\\ww 2\\venv\\Lib\\site-packages\\airtest\\utils\\logwraper.py\", line 134, in wrapper\n    res = f(*args, **kwargs)\n          ^^^^^^^^^^^^^^^^^^\n  File \"D:\\ww 2\\venv\\Lib\\site-packages\\airtest\\core\\api.py\", line 74, in connect_device\n    dev = init_device(platform, uuid, **params)\n          ^^^^^^^^^^^^^^^^^^^^^^^^^^^^^^^^^^^^^\n  File \"D:\\ww 2\\venv\\Lib\\site-packages\\airtest\\core\\api.py\", line 42, in init_device\n    dev = cls(uuid, **kwargs)\n          ^^^^^^^^^^^^^^^^^^^\n  File \"D:\\ww 2\\venv\\Lib\\site-packages\\airtest\\core\\android\\android.py\", line 59, in __init__\n    self.adb.wait_for_device()\n  File \"D:\\ww 2\\venv\\Lib\\site-packages\\airtest\\core\\android\\adb.py\", line 343, in wait_for_device\n    raisefrom(DeviceConnectionError, \"device not ready\", e)\n  File \"D:\\ww 2\\venv\\Lib\\site-packages\\airtest\\utils\\compat.py\", line 55, in raisefrom\n    raise_from(exc_type(message), exc)\n  File \"<string>\", line 3, in raise_from\nairtest.core.error.DeviceConnectionError: 'device not ready'\n", "end_time": 1742197501.6669986}}
{"tag": "info", "depth": 0, "time": 1742197501.6695123, "data": {"name": "Final Error", "traceback": "Traceback (most recent call last):\n  File \"D:\\ww 2\\venv\\Lib\\site-packages\\airtest\\core\\android\\adb.py\", line 341, in wait_for_device\n    self.cmd(\"wait-for-device\", timeout=timeout)\n  File \"D:\\ww 2\\venv\\Lib\\site-packages\\airtest\\core\\android\\adb.py\", line 221, in cmd\n    stdout, stderr = proc_communicate_timeout(proc, timeout)\n                     ^^^^^^^^^^^^^^^^^^^^^^^^^^^^^^^^^^^^^^^\n  File \"D:\\ww 2\\venv\\Lib\\site-packages\\airtest\\utils\\compat.py\", line 79, in proc_communicate_timeout\n    raise_from(exp, None)\n  File \"<string>\", line 3, in raise_from\nRuntimeError: Command ['C:\\\\Users\\\\ASUS\\\\AppData\\\\Local\\\\Android\\\\android-sdk\\\\platform-tools\\\\adb.exe', '-P', '5037', '-s', '23E0224711011260', 'wait-for-device'] timed out after 5 seconds: stdout['b'''], stderr['b''']\n\nThe above exception was the direct cause of the following exception:\n\nTraceback (most recent call last):\n  File \"D:\\ww 2\\venv\\Lib\\site-packages\\airtest\\cli\\runner.py\", line 72, in runTest\n    exec(compile(code.encode(\"utf-8\"), pyfilepath, 'exec'), self.scope)\n  File \"H:\\Uiauto_demo\\scripts\\basic\\basic_smoke.py\", line 15, in <module>\n    from scripts.home_page import home_page\n  File \"H:\\Uiauto_demo\\scripts\\home_page\\home_page.py\", line 14, in <module>\n    GeneralOperation.connect_devices()\n  File \"H:\\Uiauto_demo\\lib\\general_operation.py\", line 66, in connect_devices\n    auto_setup(__file__, logdir=log_dir, devices=[f\"Android://127.0.0.1:5037/{device_id}\"])\n  File \"D:\\ww 2\\venv\\Lib\\site-packages\\airtest\\core\\api.py\", line 141, in auto_setup\n    connect_device(dev)\n  File \"D:\\ww 2\\venv\\Lib\\site-packages\\airtest\\utils\\logwraper.py\", line 134, in wrapper\n    res = f(*args, **kwargs)\n          ^^^^^^^^^^^^^^^^^^\n  File \"D:\\ww 2\\venv\\Lib\\site-packages\\airtest\\core\\api.py\", line 74, in connect_device\n    dev = init_device(platform, uuid, **params)\n          ^^^^^^^^^^^^^^^^^^^^^^^^^^^^^^^^^^^^^\n  File \"D:\\ww 2\\venv\\Lib\\site-packages\\airtest\\core\\api.py\", line 42, in init_device\n    dev = cls(uuid, **kwargs)\n          ^^^^^^^^^^^^^^^^^^^\n  File \"D:\\ww 2\\venv\\Lib\\site-packages\\airtest\\core\\android\\android.py\", line 59, in __init__\n    self.adb.wait_for_device()\n  File \"D:\\ww 2\\venv\\Lib\\site-packages\\airtest\\core\\android\\adb.py\", line 343, in wait_for_device\n    raisefrom(DeviceConnectionError, \"device not ready\", e)\n  File \"D:\\ww 2\\venv\\Lib\\site-packages\\airtest\\utils\\compat.py\", line 55, in raisefrom\n    raise_from(exc_type(message), exc)\n  File \"<string>\", line 3, in raise_from\nairtest.core.error.DeviceConnectionError: 'device not ready'\n"}}
